<sdf version='1.7'>
  <model name='robot_mine'>
    <link name='link_chassis'>
      <inertial>
        <pose>0 0 0.099991 0 -0 0</pose>
        <mass>11.001</mass>
        <inertia>
          <ixx>0.155843</ixx>
          <ixy>0</ixy>
          <ixz>0</ixz>
          <iyy>0.238343</iyy>
          <iyz>0</iyz>
          <izz>0.375833</izz>
        </inertia>
      </inertial>
      <collision name='link_chassis_fixed_joint_lump__collision_chassis_collision'>
        <pose>0 0 0 0 -0 0</pose>
        <geometry>
          <box>
            <size>0.5 0.4 0.1</size>
          </box>
        </geometry>
      </collision>
      <collision name='link_chassis_fixed_joint_lump__metal_detector_bar_collision_1'>
        <pose>0 0 0 0 -0 0</pose>
        <geometry>
          <box>
            <size>0.2 0.05 0.0025</size>
          </box>
        </geometry>
      </collision>
      <collision name='link_chassis_fixed_joint_lump__metal_detector_holder_collision_2'>
        <pose>0 0 0 0 -0 0</pose>
        <geometry>
          <box>
            <size>0.15 0.5 0.004</size>
          </box>
        </geometry>
      </collision>
      <collision name='link_chassis_fixed_joint_lump__imu_link_collision_3'>
        <pose>0 0 0 0 -0 0</pose>
        <geometry>
          <box>
            <size>0.02 0.02 0.02</size>
          </box>
        </geometry>
        <surface>
          <contact>
            <ode/>
          </contact>
          <friction>
            <ode/>
          </friction>
        </surface>
      </collision>
      <visual name='link_chassis_visual'>
        <pose>0 0 0 0 -0 0</pose>
        <geometry>
          <box>
            <size>0.5 0.4 0.1</size>
          </box>
        </geometry>
        <material>
          <script>
            <name>Gazebo/Orange</name>
            <uri>file://media/materials/scripts/gazebo.material</uri>
          </script>
        </material>
      </visual>
      <visual name='link_chassis_visual_1'>
        <pose>0.25 0 0 0 -0 0</pose>
        <geometry>
          <box>
            <size>0.2 0.05 0.0025</size>
          </box>
        </geometry>
        <material>
          <script>
            <name>Gazebo/Orange</name>
            <uri>file://media/materials/scripts/gazebo.material</uri>
          </script>
        </material>
      </visual>
      <visual name='link_chassis_visual_2'>
        <pose>0.35 0 0 0 -0 0</pose>
        <geometry>
          <box>
            <size>0.15 0.5 0.004</size>
          </box>
        </geometry>
        <material>
          <script>
            <name>Gazebo/Orange</name>
            <uri>file://media/materials/scripts/gazebo.material</uri>
          </script>
        </material>
      </visual>
      <visual name='link_chassis_fixed_joint_lump__imu_link_visual_3'>
        <pose>0 0 0 0 -0 0</pose>
        <geometry>
          <box>
            <size>0.02 0.02 0.02</size>
          </box>
        </geometry>
      </visual>
      <gravity>1</gravity>
      <sensor name='imu_sensor' type='imu'>
        <always_on>1</always_on>
        <update_rate>1000</update_rate>
        <visualize>1</visualize>
        <topic>__default_topic__</topic>
        <plugin name='imu_plugin' filename='libgazebo_ros_imu_sensor.so'>
          <topicName>imu_data</topicName>
          <bodyName>imu_sensor_link</bodyName>
          <updateRateHZ>10.0</updateRateHZ>
          <gaussianNoise>0.0</gaussianNoise>
          <xyzOffset>0 0 0</xyzOffset>
          <rpyOffset>0 0 0</rpyOffset>
        </plugin>
        <pose>0 0 0 0 -0 0</pose>
      </sensor>
    </link>
    <joint name='joint_back_left_wheel' type='revolute'>
      <pose relative_to='link_chassis'>-0.15 -0.23 0 0 -0 0</pose>
      <parent>link_chassis</parent>
      <child>link_back_left_wheel</child>
      <axis>
        <xyz>0 1 0</xyz>
        <limit>
          <effort>10000</effort>
          <velocity>1000</velocity>
          <lower>-1e+16</lower>
          <upper>1e+16</upper>
        </limit>
        <dynamics>
          <spring_reference>0</spring_reference>
          <spring_stiffness>0</spring_stiffness>
        </dynamics>
      </axis>
    </joint>
    <link name='link_back_left_wheel'>
      <pose relative_to='joint_back_left_wheel'>0 0 0 0 -0 0</pose>
      <inertial>
        <pose>0 0 0 0 1.5707 1.5707</pose>
        <mass>1</mass>
        <inertia>
          <ixx>0.0019</ixx>
          <ixy>0</ixy>
          <ixz>0</ixz>
          <iyy>0.0019</iyy>
          <iyz>0</iyz>
          <izz>0.0032</izz>
        </inertia>
      </inertial>
      <collision name='link_back_left_wheel_fixed_joint_lump__link_right_wheel_collision_collision'>
        <pose>0 0 0 -1.5707 1.5708 0</pose>
        <geometry>
          <cylinder>
            <length>0.06</length>
            <radius>0.08</radius>
          </cylinder>
        </geometry>
      </collision>
      <visual name='link_back_left_wheel_visual_visual'>
        <pose>0 0 0 -1.5707 1.5708 0</pose>
        <geometry>
          <cylinder>
            <length>0.06</length>
            <radius>0.08</radius>
          </cylinder>
        </geometry>
      </visual>
    </link>
    <joint name='joint_back_right_wheel' type='revolute'>
      <pose relative_to='link_chassis'>-0.15 0.23 0 0 -0 0</pose>
      <parent>link_chassis</parent>
      <child>link_back_right_wheel</child>
      <axis>
        <xyz>0 1 0</xyz>
        <limit>
          <effort>10000</effort>
          <velocity>1000</velocity>
          <lower>-1e+16</lower>
          <upper>1e+16</upper>
        </limit>
        <dynamics>
          <spring_reference>0</spring_reference>
          <spring_stiffness>0</spring_stiffness>
        </dynamics>
      </axis>
    </joint>
    <link name='link_back_right_wheel'>
      <pose relative_to='joint_back_right_wheel'>0 0 0 0 -0 0</pose>
      <inertial>
        <pose>0 0 0 0 1.5707 1.5707</pose>
        <mass>1</mass>
        <inertia>
          <ixx>0.0019</ixx>
          <ixy>0</ixy>
          <ixz>0</ixz>
          <iyy>0.0019</iyy>
          <iyz>0</iyz>
          <izz>0.0032</izz>
        </inertia>
      </inertial>
      <collision name='link_back_right_wheel_fixed_joint_lump__link_right_wheel_collision_collision'>
        <pose>0 0 0 -1.5707 1.5708 0</pose>
        <geometry>
          <cylinder>
            <length>0.06</length>
            <radius>0.08</radius>
          </cylinder>
        </geometry>
      </collision>
      <visual name='link_back_right_wheel_visual_visual'>
        <pose>0 0 0 -1.5707 1.5708 0</pose>
        <geometry>
          <cylinder>
            <length>0.06</length>
            <radius>0.08</radius>
          </cylinder>
        </geometry>
      </visual>
    </link>
    <joint name='joint_front_left_wheel' type='revolute'>
      <pose relative_to='link_chassis'>0.15 -0.23 0 0 -0 0</pose>
      <parent>link_chassis</parent>
      <child>link_front_left_wheel</child>
      <axis>
        <xyz>0 1 0</xyz>
        <limit>
          <effort>10000</effort>
          <velocity>1000</velocity>
          <lower>-1e+16</lower>
          <upper>1e+16</upper>
        </limit>
        <dynamics>
          <spring_reference>0</spring_reference>
          <spring_stiffness>0</spring_stiffness>
        </dynamics>
      </axis>
    </joint>
    <link name='link_front_left_wheel'>
      <pose relative_to='joint_front_left_wheel'>0 0 0 0 -0 0</pose>
      <inertial>
        <pose>0 0 0 0 1.5707 1.5707</pose>
        <mass>1</mass>
        <inertia>
          <ixx>0.0019</ixx>
          <ixy>0</ixy>
          <ixz>0</ixz>
          <iyy>0.0019</iyy>
          <iyz>0</iyz>
          <izz>0.0032</izz>
        </inertia>
      </inertial>
      <collision name='link_front_left_wheel_fixed_joint_lump__link_right_wheel_collision_collision'>
        <pose>0 0 0 -1.5707 1.5708 0</pose>
        <geometry>
          <cylinder>
            <length>0.06</length>
            <radius>0.08</radius>
          </cylinder>
        </geometry>
      </collision>
      <visual name='link_front_left_wheel_visual_visual'>
        <pose>0 0 0 -1.5707 1.5708 0</pose>
        <geometry>
          <cylinder>
            <length>0.06</length>
            <radius>0.08</radius>
          </cylinder>
        </geometry>
      </visual>
    </link>
    <joint name='joint_front_right_wheel' type='revolute'>
      <pose relative_to='link_chassis'>0.15 0.23 0 0 -0 0</pose>
      <parent>link_chassis</parent>
      <child>link_front_right_wheel</child>
      <axis>
        <xyz>0 1 0</xyz>
        <limit>
          <effort>10000</effort>
          <velocity>1000</velocity>
          <lower>-1e+16</lower>
          <upper>1e+16</upper>
        </limit>
        <dynamics>
          <spring_reference>0</spring_reference>
          <spring_stiffness>0</spring_stiffness>
        </dynamics>
      </axis>
    </joint>
    <link name='link_front_right_wheel'>
      <pose relative_to='joint_front_right_wheel'>0 0 0 0 -0 0</pose>
      <inertial>
        <pose>0 0 0 0 1.5707 1.5707</pose>
        <mass>1</mass>
        <inertia>
          <ixx>0.0019</ixx>
          <ixy>0</ixy>
          <ixz>0</ixz>
          <iyy>0.0019</iyy>
          <iyz>0</iyz>
          <izz>0.0032</izz>
        </inertia>
      </inertial>
      <collision name='link_front_right_wheel_fixed_joint_lump__link_right_wheel_collision_collision'>
        <pose>0 0 0 -1.5707 1.5708 0</pose>
        <geometry>
          <cylinder>
            <length>0.06</length>
            <radius>0.08</radius>
          </cylinder>
        </geometry>
      </collision>
      <visual name='link_front_right_wheel_visual_visual'>
        <pose>0 0 0 -1.5707 1.5708 0</pose>
        <geometry>
          <cylinder>
            <length>0.06</length>
            <radius>0.08</radius>
          </cylinder>
        </geometry>
      </visual>
    </link>
    <static>0</static>
    <plugin name='differential_drive_controller' filename='libgazebo_ros_diff_drive.so'>
      <legacyMode>0</legacyMode>
      <alwaysOn>1</alwaysOn>
      <updateRate>20</updateRate>
      <leftJoint>joint_left_wheel</leftJoint>
      <rightJoint>joint_right_wheel</rightJoint>
      <wheelSeparation>0.2</wheelSeparation>
      <wheelDiameter>0.2</wheelDiameter>
      <torque>0.1</torque>
      <commandTopic>cmd_vel</commandTopic>
      <odometryTopic>odom</odometryTopic>
      <odometryFrame>odom</odometryFrame>
      <robotBaseFrame>link_chassis</robotBaseFrame>
    </plugin>
  </model>
</sdf>
