<?xml version="1.0"?>
<robot xmlns:xacro="http://www.ros.org/wiki/xacro">
    <xacro:macro name="link_wheel" params="name">
        <link name="${name}">
            <inertial>
              <mass value="1"/>
              <origin rpy="0 1.5707 1.5707" xyz="0 0 0"/>
              <inertia ixx="0.0019" ixy="0" ixz="0" iyy="0.0019" iyz="0" izz="0.0032"/>
            </inertial>
            <collision name="link_right_wheel_collision">
              <origin rpy="0 1.5707 1.5707" xyz="0 0 0"/>
              <geometry>
                <cylinder length="0.06" radius="0.08"/>
              </geometry>
            </collision>
            <visual name="${name}_visual">
              <origin rpy="0 1.5707 1.5707" xyz="0 0 0"/>
              <geometry>
                <cylinder length="0.06" radius="0.08"/>
              </geometry>
            </visual>
        </link>
    </xacro:macro>

    <xacro:macro name="joint_wheel" params="name child origin_xyz">
      <joint name="${name}" type="continuous">
        <origin rpy="0 0 0" xyz="${origin_xyz}"/>
        <child link="${child}"/>
        <parent link="link_chassis"/>
        <axis rpy="0 0 0" xyz="0 1 0"/>
        <limit effort="10000" velocity="1000"/>
        <joint_properties damping="1.0" friction="1.0"/>
      </joint>
      <transmission name="simple_trans">
  	<type>transmission_interface/SimpleTransmission</type>
  	<joint name="${name}">
    	<hardwareInterface>EffortJointInterface</hardwareInterface>
  	</joint>
  	<actuator name="${name}_motor">
    	<mechanicalReduction>50</mechanicalReduction>
    	<hardwareInterface>EffortJointInterface</hardwareInterface>
  	</actuator>
      </transmission>
    </xacro:macro>
    <xacro:macro name="cylinder_inertia" params="mass r l">
	  <inertia  ixx="${mass*(3*r*r+l*l)/12}" ixy = "0" ixz = "0"
		    iyy="${mass*(3*r*r+l*l)/12}" iyz = "0"
		    izz="${mass*(r*r)/2}" />
    </xacro:macro>
</robot>
